---

## ✅ Is `printf("Hello")` a **syntax** or **semantic** error in Python?

### 🔍 1. **Is it a Syntax Error?**

**No.**

- `printf("Hello")` **follows valid Python syntax**: it's a function call.
- Python's parser sees:

  - An identifier `printf`
  - Followed by parentheses
  - And a valid string literal

- So, **parsing succeeds** — no syntax error.

✅ **Conclusion**: ✅ **Not a syntax error**

---

### 🔍 2. **Is it a Semantic Error?**

Yes — specifically, it's a **NameError at runtime**.

- Python does **name resolution** (semantic analysis) during execution.
- Since `printf` is **not defined anywhere**, Python cannot resolve this name in the current scope.

➡️ So you get:

```
NameError: name 'printf' is not defined
```

✅ **Conclusion**: ✅ **Semantic/runtime error (NameError)**

---

### 🧠 So, putting it together:

```python
print("Hello")
printf("Hello")
```

- ✅ **Line 1**: parsed, compiled, executed → prints "Hello"
- ✅ **Line 2**: parsed, compiled into bytecode, but

  - At **runtime**, the **PVM throws a `NameError`** when trying to execute `printf("Hello")`

---

### 📌 Final Answer Summary:

| Code              | Syntax Error? | Semantic Error?    | Runtime Output      |
| ----------------- | ------------- | ------------------ | ------------------- |
| `print("Hello")`  | ❌ No         | ❌ No              | ✅ Prints "Hello"   |
| `printf("Hello")` | ❌ No         | ✅ Yes (NameError) | ❌ Error at runtime |

---

---

## 🧠 Key Insight:

> **Most semantic errors in Python do NOT prevent bytecode generation**.
> They are caught **at runtime** during execution by the Python Virtual Machine (PVM), **not** during bytecode compilation.

However, **there are a few rare cases** where semantic issues **can prevent bytecode generation**, typically when they are **detected during compilation** due to being **statically invalid even before execution begins**.

---

## ✅ Semantic Errors That Prevent Bytecode Generation:

### 1. **Unbound Local Error in Function Body (at compile time)**

```python
def f():
    print(x)
    x = 5
```

🔍 Output:

```
UnboundLocalError: cannot access local variable 'x' where it is not associated with a value
```

📌 Why?

- The compiler **sees an assignment to `x` later** in the function → marks `x` as a **local variable**.
- Then, `print(x)` happens **before the local variable is assigned** → invalid → compilation fails for this function.

➡️ **Bytecode is not generated for this function.**

---

### 2. **Duplicate Argument Names in Function Definitions**

```python
def f(x, x):
    pass
```

🔍 Output:

```
SyntaxError: duplicate argument 'x' in function definition
```

📌 Why?

- While the syntax of the line is correct, the **AST validator checks for duplicate arguments**.
- So this is a **semantic rule violation**, not caught by token parsing, but by validation → **bytecode not generated**.

➡️ **Fails before compilation.**

---

### 3. **Illegal `return` or `yield` outside a function**

```python
return 5
```

🔍 Output:

```
SyntaxError: 'return' outside function
```

📌 While it looks like a syntax error, this is caught **after parsing**, during AST validation.

- It's a semantic violation (wrong context).

➡️ No bytecode is generated.

---

### 4. **Illegal Use of `await`, `yield`, or `nonlocal`**

```python
nonlocal x
```

🔍 Output:

```
SyntaxError: no binding for nonlocal 'x' found
```

- Again, **parsing is okay**, but semantic checks in AST validation phase fail.
- So Python refuses to compile.

➡️ Bytecode is not generated.

---

## ✅ General Rule

| Type                           | Example                       | Bytecode Generated?        |
| ------------------------------ | ----------------------------- | -------------------------- |
| Syntax Error                   | `print("Hello`                | ❌ No                      |
| Runtime Name Error             | `printf("Hi")`                | ✅ Yes                     |
| Type Error                     | `"a" + 5`                     | ✅ Yes                     |
| Semantic Violation in AST      | `def f(x, x): pass`           | ❌ No                      |
| UnboundLocal before assignment | `print(x); x = 3` in function | ❌ No (for function block) |

---

## 🧪 You can test bytecode generation using:

```python
import dis

def test():
    print(x)
    x = 5

dis.dis(test)  # This will throw error if bytecode fails to generate
```

---

## 🧵 Summary

> **Most semantic errors in Python are detected at runtime** after bytecode is generated.
> Only a **few critical semantic violations** (caught during AST validation) **prevent bytecode generation**, like:

- Unbound local variable conflicts
- Duplicate function arguments
- Illegal control keywords in wrong context (`return`, `await`, `nonlocal`)

---

Yes — ✅ **All `NameError`s in Python are caused at runtime**, **after** bytecode is successfully generated and the script starts executing by the **Python Virtual Machine (PVM)**.

Let’s break it down clearly:

---

### 🧠 What is a `NameError`?

A `NameError` occurs when the Python interpreter tries to **access a variable or function name that has not been defined** in the current scope.

---

### ✅ When does it happen?

- **NOT during parsing** — the syntax is perfectly valid.
- **NOT during bytecode compilation** — Python compiles your code into bytecode successfully.
- ✅ **It happens during execution**, when the PVM **tries to resolve the name** at the time of running that instruction.

---

### 🔍 Example:

```python
print("Hello")
printf("World")
```

- **Step 1: Parsing** ✅ — Valid syntax
- **Step 2: Bytecode Compilation** ✅ — Bytecode is created for both lines
- **Step 3: Execution by PVM**

  - `print("Hello")` → Executes
  - `printf("World")` → `NameError: name 'printf' is not defined`

✅ So yes — the `NameError` happens **after the script starts running**, at the point where that line is executed.

---

### 📌 Special Note: Why is it not caught earlier?

Because:

- Python uses **dynamic name resolution** — it doesn’t check if names exist until that line is run.
- Unlike statically compiled languages (like C/C++) where the compiler must know everything before running, Python **defers name resolution to runtime**.

---

### ✅ Real Bytecode Evidence

Let's compile and inspect the bytecode for:

```python
print("Hello")
printf("World")
```

Using Python:

```python
import dis

def f():
    print("Hello")
    printf("World")

dis.dis(f)
```

This gives:

```
  2           0 LOAD_GLOBAL              0 (print)
              2 LOAD_CONST               1 ('Hello')
              4 CALL_FUNCTION            1
              6 POP_TOP

  3           8 LOAD_GLOBAL              1 (printf)
             10 LOAD_CONST               2 ('World')
             12 CALL_FUNCTION            1
             14 POP_TOP
             16 LOAD_CONST               0 (None)
             18 RETURN_VALUE
```

➡️ So you see: `LOAD_GLOBAL printf` exists in bytecode — no error yet.
Only when this instruction is **executed**, Python tries to **find `printf` in the current namespace**, fails, and throws `NameError`.

---

### ✅ Final Answer:

> ✅ **Yes, all `NameError`s in Python happen at runtime**, during execution by the **PVM**, **after** the script has been parsed and compiled to bytecode.
